Workbook

Sheet Bilan Financier FPM-237
A1: Nom | B1: Adhésion | C1: Maillots | D1: Assurance | E1: Match Paris | F1: Match Avril | I1: DEPENSES
A2: Big Pat (président) | B2: 20 | C2: 75 | D2: 10 | E2: 50 | I2: Achats Ballons | J2: 150
A3: Elock Son | B3: 20 | C3: 75 | D3: 10 | E3: 50 | I3: Chasubles | J3: 50
A4: Matic | B4: 20 | C4: 75 | D4: 10 | E4: 50 | I4: Match Paris | J4: 1310
A5: Patrick Dr | B5: 20 | C5: 75 | D5: 10 | E5: 50 | I5: Maillots | J5: =SUM(C2:C55) -> 2525
A6: Marco | B6: 20 | C6: 75 | D6: 10 | E6: 50 | I6: Match Cologne | J6: 100
A7: Collence | B7: 20 | C7: 75 | D7: 10 | E7: 50 | I7: Cages de but | J7: 150
A8: Tchape | B8: 20 | C8: 75 | D8: 10 | E8: 50 | I8: Assurance 2023 | J8: 134.34
A9: Patrick T (Bonificateur) | B9: x | C9: 75 | D9: x | E9: x | I9: Sandwichs Volkrange | J9: 90
A10: William | B10: 20 | C10: 75 | D10: 10 | E10: 50 | I10: Versé à Ismael | J10: 100
A11: Fabrice | B11: 20 | C11: 75 | D11: 10 | E11: 50 | I11: Virement MAIF (Assu 1er trim. 2024) | J11: 215
A12: Ismael | B12: 20 | C12: 75 | D12: 10 | E12: 50 | I12: Tournoi Longwy | J12: 100
A13: Eric B | B13: 20 | C13: 75 | D13: 10 | E13: 50 | I13: TOTAL DEPENSES : | J13: =SUM(J2:J12) -> 4924.34
A14: Christian Pépé | B14: 20 | C14: 75 | D14: 10 | E14: 50
A15: Kevin | B15: 20 | C15: 75 | D15: 10 | E15: 50 | I15: TOTAL EN CAISSE : | J15: =B60-J13 -> 290.66
A16: Boris | B16: 20 | C16: 75 | D16: 10 | E16: 50
A17: Esaie | B17: x | C17: 75 | D17: 10 | E17: x
A18: Franck K | B18: 20 | C18: 75 | D18: 10 | E18: x
A19: Stéphane TATSINKOU | B19: 20 | C19: 75 | D19: 10 | E19: 50
A20: Thierry A | B20: 20 | C20: 75 | D20: 10 | E20: 50
A21: De Souza | B21: x | C21: 75 | D21: x | E21: x
A22: Arnaud K | B22: 20 | C22: 75 | D22: 10 | E22: 50
A23: Christian N | B23: 20 | C23: 75 | D23: 10 | E23: 50
A24: Poka | B24: 20 | C24: 75 | D24: 10 | E24: x
A25: André Bilong | B25: 20 | C25: 75 | D25: 10 | E25: x
A26: Amza | B26: 20 | C26: 75 | D26: 10 | E26: x
A27: Gaby | B27: 20 | C27: x | D27: 10 | E27: x
A28: Thierry G | B28: x | C28: 70 | D28: 10 | E28: x
A29: Claude | B29: 20 | C29: 70 | D29: 10 | E29: x
A30: Pounds | B30: 20 | C30: 70 | D30: x | E30: 50
A31: Alex K | B31: x | C31: 70 | D31: 10 | E31: 50
A32: Soumah | B32: 20 | C32: 70 | D32: 10 | E32: 50
A33: Ghislain W | B33: 20 | C33: x | D33: 10 | E33: x
A34: Patrick Nkodo | B34: 20 | C34: x | D34: 10 | E34: x
A35: Alex D | B35: 20 | C35: x | D35: 10 | E35: 50
A36: Joseph Steve | B36: 20 | C36: 75 | D36: x | E36: x
A37: Emana | B37: 20 | C37: x | D37: 10 | E37: x
A38: Verratti | B38: 20 | C38: x | D38: 10 | E38: 50
A39: Benoit | B39: 20 | C39: 75 | D39: 10 | E39: 40
A40: David Eboutou | B40: 20 | C40: x | D40: 10 | E40: x
...

Sheet Contributions hebdomadiare
A1: Noms / Dates | B1: =DATE(2024,2,18) -> 45340 | C1: =DATE(YEAR(B1), MONTH(B1), DAY(B1) + 7) -> 45347 | D1: =DATE(YEAR(C1), MONTH(C1), DAY(C1) + 7) -> 45354 | E1: =DATE(YEAR(D1), MONTH(D1), DAY(D1) + 7) -> 45361 | F1: =DATE(YEAR(E1), MONTH(E1), DAY(E1) + 7) -> 45368 | G1: =DATE(YEAR(F1), MONTH(F1), DAY(F1) + 7) -> 45375 | H1: =DATE(YEAR(G1), MONTH(G1), DAY(G1) + 7) -> 45382 | I1: =DATE(YEAR(H1), MONTH(H1), DAY(H1) + 7) -> 45389 | J1: =DATE(YEAR(I1), MONTH(I1), DAY(I1) + 7) -> 45396 | ... M1: =DATE(YEAR(L1), MONTH(L1), DAY(L1) + 7) -> 45417 | N1: 45631 | O1: 19/05/24 | P1: 26/05/24 | R1: TOTAUX
A2: ='Identité membres'!A2 & " " & 'Identité membres'!B2 -> Patrick NJIWOUA | B2: 2 | C2: 2 | D2: x | E2: 2 | F2: 2 | G2: 2 | H2: x | I2: x | J2: 2 | K2: x | L2: 2 | M2: 2 | N2: 2 | O2: 2 | R2: =SUM(B2:O2) -> 20
A3: ='Identité membres'!A3 & " " & 'Identité membres'!B3 -> Celestin ELOCK SON | B3: 2 | C3: 2 | D3: x | E3: x | F3: 2 | G3: 2 | H3: 2 | I3: 2 | J3: x | K3: x | L3: 2 | M3: 1 | R3: =SUM(B3:O3) -> 15
A4: ='Identité membres'!A4 & " " & 'Identité membres'!B4 -> Steve KAMCHE | B4: 2 | C4: x | D4: 2 | E4: x | F4: 2 | G4: 2 | H4: x | I4: x | J4: x | K4: 2 | R4: =SUM(B4:O4) -> 10
A5: ='Identité membres'!A5 & " " & 'Identité membres'!B5 -> Patrick NYAT | B5: x | C5: x | D5: x | E5: x | F5: x | G5: 2 | H5: x | I5: 2 | J5: 2 | K5: x | L5: 2 | M5: 2 | R5: =SUM(B5:O5) -> 10
A6: ='Identité membres'!A6 & " " & 'Identité membres'!B6 -> Marc KOUOH | B6: x | C6: x | D6: x | E6: x | F6: x | G6: x | H6: x | I6: x | J6: x | K6: x | R6: =SUM(B6:O6) -> 0
A7: ='Identité membres'!A7 & " " & 'Identité membres'!B7 -> Collence DONFACK | B7: 2 | C7: x | D7: x | E7: x | F7: x | G7: x | H7: x | I7: x | J7: x | K7: x | R7: =SUM(B7:O7) -> 2
A8: ='Identité membres'!A8 & " " & 'Identité membres'!B8 -> Yannick TCHAPE | B8: x | C8: 2 | D8: x | E8: x | F8: 2 | G8: 2 | H8: x | I8: x | J8: x | K8: 2 | L8: 2 | R8: =SUM(B8:O8) -> 10
A9: ='Identité membres'!A9 & " " & 'Identité membres'!B9 -> Ledoux | B9: x | C9: 2 | D9: 2 | E9: 2 | F9: 2 | G9: 2 | H9: x | I9: x | J9: x | K9: 2 | L9: 1 | R9: =SUM(B9:O9) -> 13
A10: ='Identité membres'!A10 & " " & 'Identité membres'!B10 -> Williams TAKALA | B10: 2 | C10: 2 | D10: x | E10: x | F10: x | G10: x | H10: x | K10: x | R10: =SUM(B10:O10) -> 4
A11: ='Identité membres'!A11 & " " & 'Identité membres'!B11 -> Fabrice TSAKOU | B11: x | C11: x | D11: x | E11: x | F11: 2 | G11: x | H11: x | I11: x | J11: x | K11: x | L11: 2 | M11: 2 | N11: 2 | O11: 2 | R11: =SUM(B11:O11) -> 10
A12: ='Identité membres'!A12 & " " & 'Identité membres'!B12 -> Ismael DJOUKOUE | B12: 2 | C12: 2 | D12: 2 | E12: 2 | F12: 2 | G12: 2 | H12: 2 | I12: 2 | J12: 2 | K12: x | L12: 2 | R12: =SUM(B12:O12) -> 20
A13: ='Identité membres'!A13 & " " & 'Identité membres'!B13 -> Eric BOGNE | B13: x | C13: 2 | D13: x | E13: x | F13: x | H13: x | I13: x | J13: x | K13: x | R13: =SUM(B13:O13) -> 2
A14: ='Identité membres'!A14 & " " & 'Identité membres'!B14 -> Christian LEUKAM | B14: x | C14: x | D14: x | E14: x | F14: 2 | G14: x | H14: x | I14: 2 | K14: x | R14: =SUM(B14:O14) -> 4
A15: ='Identité membres'!A15 & " " & 'Identité membres'!B15 -> Kevin BOUANI | B15: x | C15: x | D15: x | E15: x | F15: x | G15: 2 | I15: 2 | R15: =SUM(B15:O15) -> 4
A16: ='Identité membres'!A16 & " " & 'Identité membres'!B16 -> Boris DJEMI | B16: x | C16: x | D16: x | E16: x | F16: 2 | G16: x | H16: x | I16: x | R16: =SUM(B16:O16) -> 2
A17: ='Identité membres'!A17 & " " & 'Identité membres'!B17 -> Thierry AMBASSA | B17: x | C17: x | D17: x | E17: x | F17: x | G17: x | H17: x | I17: x | J17: x | K17: x | L17: x | M17: x | R17: =SUM(B17:O17) -> 0
A18: ='Identité membres'!A18 & " " & 'Identité membres'!B18 -> Arnaud KOUDJOU | B18: x | C18: x | D18: x | F18: x | G18: x | I18: x | J18: x | K18: x | R18: =SUM(B18:O18) -> 0
A19: ='Identité membres'!A19 & " " & 'Identité membres'!B19 -> Christian NANYIM | B19: x | C19: x | D19: x | E19: x | F19: 2 | G19: x | H19: x | I19: x | J19: x | K19: x | R19: =SUM(B19:O19) -> 2
A20: ='Identité membres'!A20 & " " & 'Identité membres'!B20 -> Ulrich POKA | B20: 2 | C20: x | D20: x | E20: x | F20: 2 | G20: x | J20: x | R20: =SUM(B20:O20) -> 4
A21: ='Identité membres'!A21 & " " & 'Identité membres'!B21 -> Thierry GWETA | B21: x | C21: x | D21: x | E21: x | F21: x | G21: x | H21: x | I21: x | J21: x | K21: x | R21: =SUM(B21:O21) -> 0
A22: ='Identité membres'!A22 & " " & 'Identité membres'!B22 -> André BILONG | B22: x | C22: x | D22: x | E22: x | F22: x | G22: x | H22: x | I22: x | J22: x | K22: x | R22: =SUM(B22:O22) -> 0
A23: ='Identité membres'!A23 & " " & 'Identité membres'!B23 -> Amza | B23: 2 | C23: 2 | D23: 2 | E23: 2 | F23: 2 | G23: 2 | I23: 2 | J23: x | K23: 2 | L23: 2 | M23: 2 | R23: =SUM(B23:O23) -> 20
A24: ='Identité membres'!A24 & " " & 'Identité membres'!B24 -> Alex KENNE | B24: x | C24: X | D24: x | F24: 2 | H24: x | J24: 2 | K24: x | L24: 2 | M24: 2 | R24: =SUM(B24:O24) -> 8
A25: ='Identité membres'!A25 & " " & 'Identité membres'!B25 -> Eric NKOMO | B25: 2 | C25: 2 | D25: 2 | E25: 2 | F25: x | G25: x | H25: x | I25: x | J25: x | K25: x | R25: =SUM(B25:O25) -> 8
A26: ='Identité membres'!A26 & " " & 'Identité membres'!B26 -> Oscar TEMATIO | B26: 2 | C26: 2 | D26: 2 | E26: 2 | F26: 2 | G26: x | H26: x | I26: 2 | J26: x | K26: 2 | L26: 2 | M26: 2 | N26: 2 | R26: =SUM(B26:O26) -> 20
A27: ='Identité membres'!A27 & " " & 'Identité membres'!B27 -> Benoit BAHEL | B27: 2 | C27: 2 | D27: 2 | E27: 2 | F27: 2 | G27: 2 | H27: 2 | I27: 2 | J27: 2 | K27: 2 | L27: 2 | M27: 1 | R27: =SUM(B27:O27) -> 23
A28: ='Identité membres'!A28 & " " & 'Identité membres'!B28 -> Marcelo | B28: x | C28: 2 | D28: 2 | E28: x | G28: x | H28: x | I28: x | J28: x | K28: x | R28: =SUM(B28:O28) -> 4
A29: ='Identité membres'!A29 & " " & 'Identité membres'!B29 -> Mbappé | B29: 2 | C29: x | D29: 2 | E29: x | H29: x | I29: x | J29: x | R29: =SUM(B29:O29) -> 4
A30: ='Identité membres'!A30 & " " & 'Identité membres'!B30 -> Alex DJIOMENE | B30: x | C30: x | D30: x | E30: x | F30: x | G30: x | H30: x | I30: x | J30: x | K30: x | R30: =SUM(B30:O30) -> 0
A31: ='Identité membres'!A31 & " " & 'Identité membres'!B31 -> Habré | B31: x | C31: x | D31: x | E31: x | F31: 2 | H31: x | I31: x | K31: x | R31: =SUM(B31:O31) -> 2
A32: ='Identité membres'!A32 & " " & 'Identité membres'!B32 -> Patrick NKODO | B32: x | C32: x | D32: x | E32: x | F32: x | G32: x | H32: x | I32: x | K32: x | R32: =SUM(B32:O32) -> 0
A33: ='Identité membres'!A33 & " " & 'Identité membres'!B33 -> Stéphane TATSINKOU | B33: x | C33: 2 | D33: x | F33: x | G33: x | H33: x | I33: x | J33: x | K33: x | R33: =SUM(B33:O33) -> 2
A34: ='Identité membres'!A34 & " " & 'Identité membres'!B34 -> Gabriel TSIDIE | B34: x | C34: x | D34: x | E34: x | F34: x | G34: x | H34: x | I34: x | J34: x | K34: x | R34: =SUM(B34:O34) -> 0
A35: ='Identité membres'!A35 & " " & 'Identité membres'!B35 -> Christophe | B35: x | C35: x | D35: x | E35: x | F35: x | G35: x | H35: x | I35: x | J35: x | K35: x | R35: =SUM(B35:O35) -> 0
A36: ='Identité membres'!A36 & " " & 'Identité membres'!B36 -> Mohamed SOUMAH | B36: x | C36: x | D36: x | F36: x | G36: x | H36: x | I36: x | J36: x | R36: =SUM(B36:O36) -> 0
A37: ='Identité membres'!A37 & " " & 'Identité membres'!B37 -> Pounds | B37: x | C37: x | D37: x | E37: x | F37: x | G37: x | H37: x | I37: x | J37: x | K37: x | R37: =SUM(B37:O37) -> 0
A38: ='Identité membres'!A38 & " " & 'Identité membres'!B38 -> Esaie SICHELA | B38: x | C38: x | D38: x | E38: x | F38: x | G38: x | H38: x | K38: x | R38: =SUM(B38:O38) -> 0
A39: ='Identité membres'!A39 & " " & 'Identité membres'!B39 -> David Eboutou | B39: 2 | C39: x | D39: x | E39: x | F39: x | G39: x | H39: x | I39: x | J39: 2 | R39: =SUM(B39:O39) -> 4
A40: ='Identité membres'!A40 & " " & 'Identité membres'!B40 -> Lionel T | B40: x | C40: x | D40: x | E40: x | F40: x | G40: x | H40: x | I40: x | J40: x | K40: x | R40: =SUM(B40:O40) -> 0
...

Sheet Assurance-Achat matériel
A1: Membre | B1: Assu 2024 | C1: Achat Matériel | D1: Match Avril | E1: Match retour Longwy
A2: ='Identité membres'!A2 & " " & 'Identité membres'!B2 -> Patrick NJIWOUA | B2: 10 | C2: 20 | D2: 20 | E2: 10
A3: ='Identité membres'!A3 & " " & 'Identité membres'!B3 -> Celestin ELOCK SON | D3: 20 | E3: 10
A4: ='Identité membres'!A4 & " " & 'Identité membres'!B4 -> Steve KAMCHE | B4: 10 | C4: 20 | D4: 20 | E4: 10
A5: ='Identité membres'!A5 & " " & 'Identité membres'!B5 -> Patrick NYAT | B5: 10 | C5: 20 | E5: 10
A6: ='Identité membres'!A6 & " " & 'Identité membres'!B6 -> Marc KOUOH | B6: 10 | C6: 20 | D6: 20 | E6: 10
A7: ='Identité membres'!A7 & " " & 'Identité membres'!B7 -> Collence DONFACK | D7: 20 | E7: 10
A8: ='Identité membres'!A8 & " " & 'Identité membres'!B8 -> Yannick TCHAPE | B8: 10 | D8: 20 | E8: 10
A9: ='Identité membres'!A9 & " " & 'Identité membres'!B9 -> Ledoux
A10: ='Identité membres'!A10 & " " & 'Identité membres'!B10 -> Williams TAKALA | D10: 20 | E10: 10
A11: ='Identité membres'!A11 & " " & 'Identité membres'!B11 -> Fabrice TSAKOU | D11: 20 | E11: 10
A12: ='Identité membres'!A12 & " " & 'Identité membres'!B12 -> Ismael DJOUKOUE | B12: 10 | C12: 20 | D12: 20
A13: ='Identité membres'!A13 & " " & 'Identité membres'!B13 -> Eric BOGNE | B13: 10 | C13: 20 | D13: 20
A14: ='Identité membres'!A14 & " " & 'Identité membres'!B14 -> Christian LEUKAM | D14: 20
A15: ='Identité membres'!A15 & " " & 'Identité membres'!B15 -> Kevin BOUANI | D15: 20 | E15: 10
A16: ='Identité membres'!A16 & " " & 'Identité membres'!B16 -> Boris DJEMI | D16: 20 | E16: 10
A17: ='Identité membres'!A17 & " " & 'Identité membres'!B17 -> Thierry AMBASSA | D17: 20 | E17: 10
A18: ='Identité membres'!A18 & " " & 'Identité membres'!B18 -> Arnaud KOUDJOU | D18: 20
A19: ='Identité membres'!A19 & " " & 'Identité membres'!B19 -> Christian NANYIM | E19: 10
A20: ='Identité membres'!A20 & " " & 'Identité membres'!B20 -> Ulrich POKA
A21: ='Identité membres'!A21 & " " & 'Identité membres'!B21 -> Thierry GWETA | D21: 15 | E21: 10
A22: ='Identité membres'!A22 & " " & 'Identité membres'!B22 -> André BILONG | B22: 10 | C22: 20
A23: ='Identité membres'!A23 & " " & 'Identité membres'!B23 -> Amza | B23: 10 | D23: 20 | E23: 10
A24: ='Identité membres'!A24 & " " & 'Identité membres'!B24 -> Alex KENNE
A25: ='Identité membres'!A25 & " " & 'Identité membres'!B25 -> Eric NKOMO
A26: ='Identité membres'!A26 & " " & 'Identité membres'!B26 -> Oscar TEMATIO
A27: ='Identité membres'!A27 & " " & 'Identité membres'!B27 -> Benoit BAHEL | B27: 10 | D27: 20 | E27: 10
A28: ='Identité membres'!A28 & " " & 'Identité membres'!B28 -> Marcelo
A29: ='Identité membres'!A29 & " " & 'Identité membres'!B29 -> Mbappé
A30: ='Identité membres'!A30 & " " & 'Identité membres'!B30 -> Alex DJIOMENE | D30: 20
A31: ='Identité membres'!A31 & " " & 'Identité membres'!B31 -> Habré
A32: ='Identité membres'!A32 & " " & 'Identité membres'!B32 -> Patrick NKODO | D32: 20 | E32: 10
A33: ='Identité membres'!A33 & " " & 'Identité membres'!B33 -> Stéphane TATSINKOU | B33: 10 | D33: 20
A34: ='Identité membres'!A34 & " " & 'Identité membres'!B34 -> Gabriel TSIDIE | E34: 10
A35: ='Identité membres'!A35 & " " & 'Identité membres'!B35 -> Christophe | E35: 10
A36: ='Identité membres'!A36 & " " & 'Identité membres'!B36 -> Mohamed SOUMAH | E36: 10
A37: ='Identité membres'!A37 & " " & 'Identité membres'!B37 -> Pounds
A38: ='Identité membres'!A38 & " " & 'Identité membres'!B38 -> Esaie SICHELA
A39: ='Identité membres'!A39 & " " & 'Identité membres'!B39 -> David Eboutou | B39: 10 | D39: 20
A40: ='Identité membres'!A40 & " " & 'Identité membres'!B40 -> Lionel T
...

Sheet Oeufs-Boissons
A1: Noms / Dates | B1: =DATE(2024,2,18) -> 45340 | E1: =DATE(2024,2,25) -> 45347 | H1: =DATE(2024,3,3) -> 45354 | K1: =DATE(2024,10,3) -> 45568 | N1: 17/03/2024 | Q1: 24/03/2024 | T1: 31/03/2024 | W1: 45477 | Z1: 14/04/2024 | AC1: 21/04/2024 | AF1: 28/04/2024
B2: Oeufs | C2: Boissons | D2: Jeu | E2: Oeufs | F2: Boissons | G2: Jeu | H2: Oeufs | I2: Boissons | J2: Jeu | K2: Oeufs | L2: Boissons | M2: Jeu | N2: Oeufs | O2: Boissons | P2: Jeu | Q2: Oeufs | R2: Boissons | S2: Jeu | T2: Oeufs | U2: Boissons | V2: Jeu | W2: Oeufs | X2: Boissons | Y2: Jeu | Z2: Oeufs | AA2: Boissons | AB2: Jeu | AC2: Oeufs | AD2: Boissons | AE2: Jeu | AF2: Oeufs | AG2: Boissons | AH2: Jeu
A3: ='Identité membres'!A2 & " " & 'Identité membres'!B2 -> Patrick NJIWOUA | C3: 1
A4: ='Identité membres'!A3 & " " & 'Identité membres'!B3 -> Celestin ELOCK SON
A5: ='Identité membres'!A4 & " " & 'Identité membres'!B4 -> Steve KAMCHE
A6: ='Identité membres'!A5 & " " & 'Identité membres'!B5 -> Patrick NYAT
A7: ='Identité membres'!A6 & " " & 'Identité membres'!B6 -> Marc KOUOH
A8: ='Identité membres'!A7 & " " & 'Identité membres'!B7 -> Collence DONFACK
A9: ='Identité membres'!A8 & " " & 'Identité membres'!B8 -> Yannick TCHAPE
A10: ='Identité membres'!A9 & " " & 'Identité membres'!B9 -> Ledoux
A11: ='Identité membres'!A10 & " " & 'Identité membres'!B10 -> Williams TAKALA
A12: ='Identité membres'!A11 & " " & 'Identité membres'!B11 -> Fabrice TSAKOU
A13: ='Identité membres'!A12 & " " & 'Identité membres'!B12 -> Ismael DJOUKOUE
A14: ='Identité membres'!A13 & " " & 'Identité membres'!B13 -> Eric BOGNE | E14: 1
A15: ='Identité membres'!A14 & " " & 'Identité membres'!B14 -> Christian LEUKAM | F15: 1
A16: ='Identité membres'!A15 & " " & 'Identité membres'!B15 -> Kevin BOUANI | Q16: 1
A17: ='Identité membres'!A16 & " " & 'Identité membres'!B16 -> Boris DJEMI | O17: 1
A18: ='Identité membres'!A17 & " " & 'Identité membres'!B17 -> Thierry AMBASSA
A19: ='Identité membres'!A18 & " " & 'Identité membres'!B18 -> Arnaud KOUDJOU
A20: ='Identité membres'!A19 & " " & 'Identité membres'!B19 -> Christian NANYIM | R20: 1
A21: ='Identité membres'!A20 & " " & 'Identité membres'!B20 -> Ulrich POKA | AC21: 1
A22: ='Identité membres'!A21 & " " & 'Identité membres'!B21 -> Thierry GWETA
A23: ='Identité membres'!A22 & " " & 'Identité membres'!B22 -> André BILONG
A24: ='Identité membres'!A23 & " " & 'Identité membres'!B23 -> Amza
A25: ='Identité membres'!A24 & " " & 'Identité membres'!B24 -> Alex KENNE
A26: ='Identité membres'!A25 & " " & 'Identité membres'!B25 -> Eric NKOMO
A27: ='Identité membres'!A26 & " " & 'Identité membres'!B26 -> Oscar TEMATIO | B27: 1
A28: ='Identité membres'!A27 & " " & 'Identité membres'!B27 -> Benoit BAHEL
A29: ='Identité membres'!A28 & " " & 'Identité membres'!B28 -> Marcelo
A30: ='Identité membres'!A29 & " " & 'Identité membres'!B29 -> Mbappé
A31: ='Identité membres'!A30 & " " & 'Identité membres'!B30 -> Alex DJIOMENE
A32: ='Identité membres'!A31 & " " & 'Identité membres'!B31 -> Habré
A33: ='Identité membres'!A32 & " " & 'Identité membres'!B32 -> Patrick NKODO | H33: 1
A34: ='Identité membres'!A33 & " " & 'Identité membres'!B33 -> Stéphane TATSINKOU | I34: 1
A35: ='Identité membres'!A34 & " " & 'Identité membres'!B34 -> Gabriel TSIDIE
A36: ='Identité membres'!A35 & " " & 'Identité membres'!B35 -> Christophe
A37: ='Identité membres'!A36 & " " & 'Identité membres'!B36 -> Mohamed SOUMAH | N37: 1
A38: ='Identité membres'!A37 & " " & 'Identité membres'!B37 -> Pounds
A39: ='Identité membres'!A38 & " " & 'Identité membres'!B38 -> Esaie SICHELA
A40: ='Identité membres'!A39 & " " & 'Identité membres'!B39 -> David Eboutou
...

Sheet Identité membres
A1: Prénom | B1: Nom | C1: Surnom | D1: Localité | E1: Telephone
A2: Patrick | B2: NJIWOUA | C2: Président | D2: Thionville
A3: Celestin | B3: ELOCK SON | D3: Metz
A4: Steve | B4: KAMCHE | C4: Matic | D4: Nancy | E4: +33758111145
A5: Patrick | B5: NYAT | D5: Metz
A6: Marc | B6: KOUOH | D6: Thionville
A7: Collence | B7: DONFACK | D7: Metz
A8: Yannick | B8: TCHAPE | D8: Metz
B9: Ledoux | D9: Metz
A10: Williams | B10: TAKALA | D10: Metz
A11: Fabrice | B11: TSAKOU | C11: Lukaku | D11: Luxembourg
A12: Ismael | B12: DJOUKOUE | D12: Thionville
A13: Eric | B13: BOGNE | D13: Talange
A14: Christian | B14: LEUKAM | D14: Metz
A15: Kevin | B15: BOUANI | D15: Metz
A16: Boris | B16: DJEMI | C16: Bafia | D16: Metz
A17: Thierry | B17: AMBASSA | D17: Thionville
A18: Arnaud | B18: KOUDJOU | D18: Thionville
A19: Christian | B19: NANYIM | D19: Metz
A20: Ulrich | B20: POKA | D20: Luxembourg | E20: +352661285661
A21: Thierry | B21: GWETA | D21: Thionville
A22: André | B22: BILONG | C22: La Pépite | D22: Thionville
B23: Amza | D23: Metz
A24: Alex | B24: KENNE | D24: Thionville
A25: Eric | B25: NKOMO | C25: Emana | D25: Thionville
A26: Oscar | B26: TEMATIO | C26: Verratti | D26: Metz
A27: Benoit | B27: BAHEL | D27: Thionville
B28: Marcelo | D28: Metz
B29: Mbappé | D29: Metz
A30: Alex | B30: DJIOMENE | D30: Metz
B31: Habré | D31: Metz
A32: Patrick | B32: NKODO | C32: Le Pro | D32: Metz
A33: Stéphane | B33: TATSINKOU | C33: Doc | D33: Forbach
A34: Gabriel | B34: TSIDIE | C34: Gaby | D34: Metz
B35: Christophe | D35: Metz
A36: Mohamed | B36: SOUMAH | C36: Momo | D36: Thionville
B37: Pounds | D37: Luxembourg
A38: Esaie | B38: SICHELA | D38: Thionville
B39: David Eboutou | D39: Thionville
B40: Lionel T
...

Sheet Contribution Annuelle
A1: NOMS | B1: Année 2025
A2: Big Pat (Prési) | B2: 100
A3: Big Marco | B3: 100
A4: Fabrice | B4: 100
A5: Arnaud K | B5: 100
A6: Eric B | B6: 100
A7: Collence | B7: 100
A8: Elock Son | B8: 100
A9: Claude M | B9: 100
A10: Bilong | B10: 100
A11: Davies | B11: 100
A12: Eric Emana | B12: 100
A13: Esaie | B13: 100
... A61: PH | B61: 10
A65: TOTAL | B65: =SUM(B1:B62) -> 4830
A67: RESTE EN CAISSE 2023 | B67: 290.66
A68: RESTE EN CAISSE 2024 | B68: 91.96
A70: TOTAL EN CAISSE | B70: =SUM(B65:B68) -> 5212.62
A73: DEPENSES
A74: Match contre 2-0 Lux | B74: 500
A75: Assurance MAIF | B75: 669.21
A76: Achat des Chasubles | B76: 363.6
A77: Match contre Longwy | B77: 463.92
A78: Trousse Médicale | B78: 99.76
A79: Affiliation à la League | B79: 300
A80: Facture eaux et Jus à Reims | B80: 34.43
A81: Match Amical contre Paris | B81: 158
A82: Match retour contre 2-0 Lux | B82: 20
A83: Match Amical contre Cap Vert | B83: 150
A84: Achat maillot (avanace) | B84: 400
A85: Eau 1er match de la league | B85: 15.09
... A91: Travaux Club House | B91: 50
A94: TOTAL DEPENSES | B94: =SUM(B74:B93) -> 3989.01
A98: RESTE EN CAISSE | B98: =B70-B94 -> 1223.61
